[2025-10-20T13:53:44.171+0000] {local_task_job_runner.py:123} INFO - ::group::Pre task execution logs
[2025-10-20T13:53:44.188+0000] {taskinstance.py:2612} INFO - Dependencies all met for dep_context=non-requeueable deps ti=<TaskInstance: Anomaly_Detection_Daily.send_email_notification manual__2025-10-20T13:51:08.202586+00:00 [queued]>
[2025-10-20T13:53:44.199+0000] {taskinstance.py:2612} INFO - Dependencies all met for dep_context=requeueable deps ti=<TaskInstance: Anomaly_Detection_Daily.send_email_notification manual__2025-10-20T13:51:08.202586+00:00 [queued]>
[2025-10-20T13:53:44.200+0000] {taskinstance.py:2865} INFO - Starting attempt 1 of 1
[2025-10-20T13:53:44.239+0000] {taskinstance.py:2888} INFO - Executing <Task(PythonOperator): send_email_notification> on 2025-10-20 13:51:08.202586+00:00
[2025-10-20T13:53:44.250+0000] {logging_mixin.py:190} WARNING - /home/airflow/.local/lib/python3.12/site-packages/airflow/task/task_runner/standard_task_runner.py:70 DeprecationWarning: This process (pid=1119) is multi-threaded, use of fork() may lead to deadlocks in the child.
[2025-10-20T13:53:44.249+0000] {standard_task_runner.py:104} INFO - Running: ['airflow', 'tasks', 'run', 'Anomaly_Detection_Daily', 'send_email_notification', 'manual__2025-10-20T13:51:08.202586+00:00', '--job-id', '96', '--raw', '--subdir', 'DAGS_FOLDER/anomaly_detection.py', '--cfg-path', '/tmp/tmp9w8err4v']
[2025-10-20T13:53:44.252+0000] {standard_task_runner.py:72} INFO - Started process 1135 to run task
[2025-10-20T13:53:44.252+0000] {standard_task_runner.py:105} INFO - Job 96: Subtask send_email_notification
[2025-10-20T13:53:44.325+0000] {logging_mixin.py:190} WARNING - /home/airflow/.local/lib/python3.12/site-packages/airflow/settings.py:209 DeprecationWarning: The sql_alchemy_conn option in [core] has been moved to the sql_alchemy_conn option in [database] - the old setting has been used, but please update your config.
[2025-10-20T13:53:44.450+0000] {task_command.py:467} INFO - Running <TaskInstance: Anomaly_Detection_Daily.send_email_notification manual__2025-10-20T13:51:08.202586+00:00 [running]> on host 9a3624a83b26
[2025-10-20T13:53:44.689+0000] {taskinstance.py:3131} INFO - Exporting env vars: AIRFLOW_CTX_DAG_OWNER='airflow' AIRFLOW_CTX_DAG_ID='Anomaly_Detection_Daily' AIRFLOW_CTX_TASK_ID='send_email_notification' AIRFLOW_CTX_EXECUTION_DATE='2025-10-20T13:51:08.202586+00:00' AIRFLOW_CTX_TRY_NUMBER='1' AIRFLOW_CTX_DAG_RUN_ID='manual__2025-10-20T13:51:08.202586+00:00'
[2025-10-20T13:53:44.691+0000] {taskinstance.py:731} INFO - ::endgroup::
[2025-10-20T13:53:44.752+0000] {taskinstance.py:3310} ERROR - Task failed with exception
Traceback (most recent call last):
  File "/home/airflow/.local/lib/python3.12/site-packages/airflow/models/taskinstance.py", line 767, in _execute_task
    result = _execute_callable(context=context, **execute_callable_kwargs)
             ^^^^^^^^^^^^^^^^^^^^^^^^^^^^^^^^^^^^^^^^^^^^^^^^^^^^^^^^^^^^^
  File "/home/airflow/.local/lib/python3.12/site-packages/airflow/models/taskinstance.py", line 733, in _execute_callable
    return ExecutionCallableRunner(
           ^^^^^^^^^^^^^^^^^^^^^^^^
  File "/home/airflow/.local/lib/python3.12/site-packages/airflow/utils/operator_helpers.py", line 252, in run
    return self.func(*args, **kwargs)
           ^^^^^^^^^^^^^^^^^^^^^^^^^^
  File "/home/airflow/.local/lib/python3.12/site-packages/airflow/models/baseoperator.py", line 406, in wrapper
    return func(self, *args, **kwargs)
           ^^^^^^^^^^^^^^^^^^^^^^^^^^^
  File "/home/airflow/.local/lib/python3.12/site-packages/airflow/operators/python.py", line 238, in execute
    return_value = self.execute_callable()
                   ^^^^^^^^^^^^^^^^^^^^^^^
  File "/home/airflow/.local/lib/python3.12/site-packages/airflow/operators/python.py", line 256, in execute_callable
    return runner.run(*self.op_args, **self.op_kwargs)
           ^^^^^^^^^^^^^^^^^^^^^^^^^^^^^^^^^^^^^^^^^^^
  File "/home/airflow/.local/lib/python3.12/site-packages/airflow/utils/operator_helpers.py", line 252, in run
    return self.func(*args, **kwargs)
           ^^^^^^^^^^^^^^^^^^^^^^^^^^
  File "/opt/airflow/dags/anomaly_detection.py", line 88, in send_mail_notification
    forecasts = results.get_forecast(steps=7, exog = sales_data_test[exogenous]).conf_int(alpha=0.01)
                                                     ^^^^^^^^^^^^^^^
NameError: name 'sales_data_test' is not defined
[2025-10-20T13:53:44.780+0000] {taskinstance.py:1225} INFO - Marking task as FAILED. dag_id=Anomaly_Detection_Daily, task_id=send_email_notification, run_id=manual__2025-10-20T13:51:08.202586+00:00, execution_date=20251020T135108, start_date=20251020T135344, end_date=20251020T135344
[2025-10-20T13:53:44.872+0000] {taskinstance.py:340} INFO - ::group::Post task execution logs
[2025-10-20T13:53:44.874+0000] {standard_task_runner.py:124} ERROR - Failed to execute job 96 for task send_email_notification (name 'sales_data_test' is not defined; 1135)
Traceback (most recent call last):
  File "/home/airflow/.local/lib/python3.12/site-packages/airflow/task/task_runner/standard_task_runner.py", line 117, in _start_by_fork
    ret = args.func(args, dag=self.dag)
          ^^^^^^^^^^^^^^^^^^^^^^^^^^^^^
  File "/home/airflow/.local/lib/python3.12/site-packages/airflow/cli/cli_config.py", line 49, in command
    return func(*args, **kwargs)
           ^^^^^^^^^^^^^^^^^^^^^
  File "/home/airflow/.local/lib/python3.12/site-packages/airflow/utils/cli.py", line 115, in wrapper
    return f(*args, **kwargs)
           ^^^^^^^^^^^^^^^^^^
  File "/home/airflow/.local/lib/python3.12/site-packages/airflow/cli/commands/task_command.py", line 483, in task_run
    task_return_code = _run_task_by_selected_method(args, _dag, ti)
                       ^^^^^^^^^^^^^^^^^^^^^^^^^^^^^^^^^^^^^^^^^^^^
  File "/home/airflow/.local/lib/python3.12/site-packages/airflow/cli/commands/task_command.py", line 256, in _run_task_by_selected_method
    return _run_raw_task(args, ti)
           ^^^^^^^^^^^^^^^^^^^^^^^
  File "/home/airflow/.local/lib/python3.12/site-packages/airflow/cli/commands/task_command.py", line 341, in _run_raw_task
    return ti._run_raw_task(
           ^^^^^^^^^^^^^^^^^
  File "/home/airflow/.local/lib/python3.12/site-packages/airflow/utils/session.py", line 97, in wrapper
    return func(*args, session=session, **kwargs)
           ^^^^^^^^^^^^^^^^^^^^^^^^^^^^^^^^^^^^^^
  File "/home/airflow/.local/lib/python3.12/site-packages/airflow/models/taskinstance.py", line 3004, in _run_raw_task
    return _run_raw_task(
           ^^^^^^^^^^^^^^
  File "/home/airflow/.local/lib/python3.12/site-packages/airflow/models/taskinstance.py", line 273, in _run_raw_task
    TaskInstance._execute_task_with_callbacks(
  File "/home/airflow/.local/lib/python3.12/site-packages/airflow/models/taskinstance.py", line 3158, in _execute_task_with_callbacks
    result = self._execute_task(context, task_orig)
             ^^^^^^^^^^^^^^^^^^^^^^^^^^^^^^^^^^^^^^
  File "/home/airflow/.local/lib/python3.12/site-packages/airflow/models/taskinstance.py", line 3182, in _execute_task
    return _execute_task(self, context, task_orig)
           ^^^^^^^^^^^^^^^^^^^^^^^^^^^^^^^^^^^^^^^
  File "/home/airflow/.local/lib/python3.12/site-packages/airflow/models/taskinstance.py", line 767, in _execute_task
    result = _execute_callable(context=context, **execute_callable_kwargs)
             ^^^^^^^^^^^^^^^^^^^^^^^^^^^^^^^^^^^^^^^^^^^^^^^^^^^^^^^^^^^^^
  File "/home/airflow/.local/lib/python3.12/site-packages/airflow/models/taskinstance.py", line 733, in _execute_callable
    return ExecutionCallableRunner(
           ^^^^^^^^^^^^^^^^^^^^^^^^
  File "/home/airflow/.local/lib/python3.12/site-packages/airflow/utils/operator_helpers.py", line 252, in run
    return self.func(*args, **kwargs)
           ^^^^^^^^^^^^^^^^^^^^^^^^^^
  File "/home/airflow/.local/lib/python3.12/site-packages/airflow/models/baseoperator.py", line 406, in wrapper
    return func(self, *args, **kwargs)
           ^^^^^^^^^^^^^^^^^^^^^^^^^^^
  File "/home/airflow/.local/lib/python3.12/site-packages/airflow/operators/python.py", line 238, in execute
    return_value = self.execute_callable()
                   ^^^^^^^^^^^^^^^^^^^^^^^
  File "/home/airflow/.local/lib/python3.12/site-packages/airflow/operators/python.py", line 256, in execute_callable
    return runner.run(*self.op_args, **self.op_kwargs)
           ^^^^^^^^^^^^^^^^^^^^^^^^^^^^^^^^^^^^^^^^^^^
  File "/home/airflow/.local/lib/python3.12/site-packages/airflow/utils/operator_helpers.py", line 252, in run
    return self.func(*args, **kwargs)
           ^^^^^^^^^^^^^^^^^^^^^^^^^^
  File "/opt/airflow/dags/anomaly_detection.py", line 88, in send_mail_notification
    forecasts = results.get_forecast(steps=7, exog = sales_data_test[exogenous]).conf_int(alpha=0.01)
                                                     ^^^^^^^^^^^^^^^
NameError: name 'sales_data_test' is not defined
[2025-10-20T13:53:44.912+0000] {local_task_job_runner.py:266} INFO - Task exited with return code 1
[2025-10-20T13:53:44.936+0000] {taskinstance.py:3900} INFO - 0 downstream tasks scheduled from follow-on schedule check
[2025-10-20T13:53:44.938+0000] {local_task_job_runner.py:245} INFO - ::endgroup::
