[2025-10-17T19:17:42.694+0000] {local_task_job_runner.py:123} INFO - ::group::Pre task execution logs
[2025-10-17T19:17:42.713+0000] {taskinstance.py:2612} INFO - Dependencies all met for dep_context=non-requeueable deps ti=<TaskInstance: Anomaly_Detection_Daily.calculate_forecast_range manual__2025-10-17T19:17:32.315264+00:00 [queued]>
[2025-10-17T19:17:42.723+0000] {taskinstance.py:2612} INFO - Dependencies all met for dep_context=requeueable deps ti=<TaskInstance: Anomaly_Detection_Daily.calculate_forecast_range manual__2025-10-17T19:17:32.315264+00:00 [queued]>
[2025-10-17T19:17:42.724+0000] {taskinstance.py:2865} INFO - Starting attempt 1 of 1
[2025-10-17T19:17:42.750+0000] {taskinstance.py:2888} INFO - Executing <Task(PythonOperator): calculate_forecast_range> on 2025-10-17 19:17:32.315264+00:00
[2025-10-17T19:17:42.762+0000] {logging_mixin.py:190} WARNING - /home/airflow/.local/lib/python3.12/site-packages/airflow/task/task_runner/standard_task_runner.py:70 DeprecationWarning: This process (pid=613) is multi-threaded, use of fork() may lead to deadlocks in the child.
[2025-10-17T19:17:42.771+0000] {standard_task_runner.py:72} INFO - Started process 629 to run task
[2025-10-17T19:17:42.761+0000] {standard_task_runner.py:104} INFO - Running: ['airflow', 'tasks', 'run', 'Anomaly_Detection_Daily', 'calculate_forecast_range', 'manual__2025-10-17T19:17:32.315264+00:00', '--job-id', '30', '--raw', '--subdir', 'DAGS_FOLDER/anomaly_detection.py', '--cfg-path', '/tmp/tmp3kwdjuc_']
[2025-10-17T19:17:42.788+0000] {standard_task_runner.py:105} INFO - Job 30: Subtask calculate_forecast_range
[2025-10-17T19:17:42.811+0000] {logging_mixin.py:190} WARNING - /home/airflow/.local/lib/python3.12/site-packages/airflow/settings.py:209 DeprecationWarning: The sql_alchemy_conn option in [core] has been moved to the sql_alchemy_conn option in [database] - the old setting has been used, but please update your config.
[2025-10-17T19:17:42.853+0000] {task_command.py:467} INFO - Running <TaskInstance: Anomaly_Detection_Daily.calculate_forecast_range manual__2025-10-17T19:17:32.315264+00:00 [running]> on host 67c6a9343032
[2025-10-17T19:17:42.932+0000] {taskinstance.py:3131} INFO - Exporting env vars: AIRFLOW_CTX_DAG_OWNER='airflow' AIRFLOW_CTX_DAG_ID='Anomaly_Detection_Daily' AIRFLOW_CTX_TASK_ID='calculate_forecast_range' AIRFLOW_CTX_EXECUTION_DATE='2025-10-17T19:17:32.315264+00:00' AIRFLOW_CTX_TRY_NUMBER='1' AIRFLOW_CTX_DAG_RUN_ID='manual__2025-10-17T19:17:32.315264+00:00'
[2025-10-17T19:17:42.933+0000] {taskinstance.py:731} INFO - ::endgroup::
[2025-10-17T19:18:33.995+0000] {logging_mixin.py:190} WARNING - /home/airflow/.local/lib/python3.12/site-packages/statsmodels/base/model.py:607 ConvergenceWarning: Maximum Likelihood optimization failed to converge. Check mle_retvals
[2025-10-17T19:19:01.881+0000] {logging_mixin.py:190} WARNING - /home/airflow/.local/lib/python3.12/site-packages/statsmodels/base/model.py:607 ConvergenceWarning: Maximum Likelihood optimization failed to converge. Check mle_retvals
[2025-10-17T19:19:02.473+0000] {logging_mixin.py:190} WARNING - /home/airflow/.local/lib/python3.12/site-packages/statsmodels/base/model.py:607 ConvergenceWarning: Maximum Likelihood optimization failed to converge. Check mle_retvals
[2025-10-17T19:19:25.628+0000] {taskinstance.py:3310} ERROR - Task failed with exception
Traceback (most recent call last):
  File "/home/airflow/.local/lib/python3.12/site-packages/airflow/models/taskinstance.py", line 767, in _execute_task
    result = _execute_callable(context=context, **execute_callable_kwargs)
             ^^^^^^^^^^^^^^^^^^^^^^^^^^^^^^^^^^^^^^^^^^^^^^^^^^^^^^^^^^^^^
  File "/home/airflow/.local/lib/python3.12/site-packages/airflow/models/taskinstance.py", line 733, in _execute_callable
    return ExecutionCallableRunner(
           ^^^^^^^^^^^^^^^^^^^^^^^^
  File "/home/airflow/.local/lib/python3.12/site-packages/airflow/utils/operator_helpers.py", line 252, in run
    return self.func(*args, **kwargs)
           ^^^^^^^^^^^^^^^^^^^^^^^^^^
  File "/home/airflow/.local/lib/python3.12/site-packages/airflow/models/baseoperator.py", line 406, in wrapper
    return func(self, *args, **kwargs)
           ^^^^^^^^^^^^^^^^^^^^^^^^^^^
  File "/home/airflow/.local/lib/python3.12/site-packages/airflow/operators/python.py", line 238, in execute
    return_value = self.execute_callable()
                   ^^^^^^^^^^^^^^^^^^^^^^^
  File "/home/airflow/.local/lib/python3.12/site-packages/airflow/operators/python.py", line 256, in execute_callable
    return runner.run(*self.op_args, **self.op_kwargs)
           ^^^^^^^^^^^^^^^^^^^^^^^^^^^^^^^^^^^^^^^^^^^
  File "/home/airflow/.local/lib/python3.12/site-packages/airflow/utils/operator_helpers.py", line 252, in run
    return self.func(*args, **kwargs)
           ^^^^^^^^^^^^^^^^^^^^^^^^^^
  File "/opt/airflow/dags/anomaly_detection.py", line 94, in calculate_forecase_range
    subject = "Anomaly Detection for %f" % (datetime.today().strftime('%Y-%m-%d'))
              ~~~~~~~~~~~~~~~~~~~~~~~~~~~^~~~~~~~~~~~~~~~~~~~~~~~~~~~~~~~~~~~~~~~~
TypeError: must be real number, not str
[2025-10-17T19:19:25.645+0000] {taskinstance.py:1225} INFO - Marking task as FAILED. dag_id=Anomaly_Detection_Daily, task_id=calculate_forecast_range, run_id=manual__2025-10-17T19:17:32.315264+00:00, execution_date=20251017T191732, start_date=20251017T191742, end_date=20251017T191925
[2025-10-17T19:19:25.681+0000] {taskinstance.py:340} INFO - ::group::Post task execution logs
[2025-10-17T19:19:25.682+0000] {standard_task_runner.py:124} ERROR - Failed to execute job 30 for task calculate_forecast_range (must be real number, not str; 629)
Traceback (most recent call last):
  File "/home/airflow/.local/lib/python3.12/site-packages/airflow/task/task_runner/standard_task_runner.py", line 117, in _start_by_fork
    ret = args.func(args, dag=self.dag)
          ^^^^^^^^^^^^^^^^^^^^^^^^^^^^^
  File "/home/airflow/.local/lib/python3.12/site-packages/airflow/cli/cli_config.py", line 49, in command
    return func(*args, **kwargs)
           ^^^^^^^^^^^^^^^^^^^^^
  File "/home/airflow/.local/lib/python3.12/site-packages/airflow/utils/cli.py", line 115, in wrapper
    return f(*args, **kwargs)
           ^^^^^^^^^^^^^^^^^^
  File "/home/airflow/.local/lib/python3.12/site-packages/airflow/cli/commands/task_command.py", line 483, in task_run
    task_return_code = _run_task_by_selected_method(args, _dag, ti)
                       ^^^^^^^^^^^^^^^^^^^^^^^^^^^^^^^^^^^^^^^^^^^^
  File "/home/airflow/.local/lib/python3.12/site-packages/airflow/cli/commands/task_command.py", line 256, in _run_task_by_selected_method
    return _run_raw_task(args, ti)
           ^^^^^^^^^^^^^^^^^^^^^^^
  File "/home/airflow/.local/lib/python3.12/site-packages/airflow/cli/commands/task_command.py", line 341, in _run_raw_task
    return ti._run_raw_task(
           ^^^^^^^^^^^^^^^^^
  File "/home/airflow/.local/lib/python3.12/site-packages/airflow/utils/session.py", line 97, in wrapper
    return func(*args, session=session, **kwargs)
           ^^^^^^^^^^^^^^^^^^^^^^^^^^^^^^^^^^^^^^
  File "/home/airflow/.local/lib/python3.12/site-packages/airflow/models/taskinstance.py", line 3004, in _run_raw_task
    return _run_raw_task(
           ^^^^^^^^^^^^^^
  File "/home/airflow/.local/lib/python3.12/site-packages/airflow/models/taskinstance.py", line 273, in _run_raw_task
    TaskInstance._execute_task_with_callbacks(
  File "/home/airflow/.local/lib/python3.12/site-packages/airflow/models/taskinstance.py", line 3158, in _execute_task_with_callbacks
    result = self._execute_task(context, task_orig)
             ^^^^^^^^^^^^^^^^^^^^^^^^^^^^^^^^^^^^^^
  File "/home/airflow/.local/lib/python3.12/site-packages/airflow/models/taskinstance.py", line 3182, in _execute_task
    return _execute_task(self, context, task_orig)
           ^^^^^^^^^^^^^^^^^^^^^^^^^^^^^^^^^^^^^^^
  File "/home/airflow/.local/lib/python3.12/site-packages/airflow/models/taskinstance.py", line 767, in _execute_task
    result = _execute_callable(context=context, **execute_callable_kwargs)
             ^^^^^^^^^^^^^^^^^^^^^^^^^^^^^^^^^^^^^^^^^^^^^^^^^^^^^^^^^^^^^
  File "/home/airflow/.local/lib/python3.12/site-packages/airflow/models/taskinstance.py", line 733, in _execute_callable
    return ExecutionCallableRunner(
           ^^^^^^^^^^^^^^^^^^^^^^^^
  File "/home/airflow/.local/lib/python3.12/site-packages/airflow/utils/operator_helpers.py", line 252, in run
    return self.func(*args, **kwargs)
           ^^^^^^^^^^^^^^^^^^^^^^^^^^
  File "/home/airflow/.local/lib/python3.12/site-packages/airflow/models/baseoperator.py", line 406, in wrapper
    return func(self, *args, **kwargs)
           ^^^^^^^^^^^^^^^^^^^^^^^^^^^
  File "/home/airflow/.local/lib/python3.12/site-packages/airflow/operators/python.py", line 238, in execute
    return_value = self.execute_callable()
                   ^^^^^^^^^^^^^^^^^^^^^^^
  File "/home/airflow/.local/lib/python3.12/site-packages/airflow/operators/python.py", line 256, in execute_callable
    return runner.run(*self.op_args, **self.op_kwargs)
           ^^^^^^^^^^^^^^^^^^^^^^^^^^^^^^^^^^^^^^^^^^^
  File "/home/airflow/.local/lib/python3.12/site-packages/airflow/utils/operator_helpers.py", line 252, in run
    return self.func(*args, **kwargs)
           ^^^^^^^^^^^^^^^^^^^^^^^^^^
  File "/opt/airflow/dags/anomaly_detection.py", line 94, in calculate_forecase_range
    subject = "Anomaly Detection for %f" % (datetime.today().strftime('%Y-%m-%d'))
              ~~~~~~~~~~~~~~~~~~~~~~~~~~~^~~~~~~~~~~~~~~~~~~~~~~~~~~~~~~~~~~~~~~~~
TypeError: must be real number, not str
[2025-10-17T19:19:25.712+0000] {local_task_job_runner.py:266} INFO - Task exited with return code 1
[2025-10-17T19:19:25.722+0000] {taskinstance.py:3900} INFO - 0 downstream tasks scheduled from follow-on schedule check
[2025-10-17T19:19:25.724+0000] {local_task_job_runner.py:245} INFO - ::endgroup::
